<?xml version="1.0"?>
<robot xmlns:xacro="http://ros.org/wiki/xacro" name="Sigyn">
  <self_collide>false</self_collide>
  <pose>0 0 0.2 0 0 0</pose>
  <static>false</static>
  <xacro:arg name="use_ros2_control" default="true" />
  <xacro:arg name="sim_mode" default="false" />

  <xacro:include filename="$(find description)/urdf/common_macros.xacro" />
  <xacro:include filename="$(find description)/urdf/inertials.xacro" />
  <xacro:property name="props" value="${xacro.load_yaml('sigyn_config.yaml')}" />
  <xacro:include filename="$(find description)/urdf/sigyn_base_macro.urdf.xacro" />
  <xacro:include filename="$(find description)/urdf/sigyn_caster_wheel_macro.urdf.xacro" />
  <xacro:include filename="$(find description)/urdf/sigyn_wheels_macro.urdf.xacro" />

  <xacro:if value="$(arg use_ros2_control)">
    <xacro:include filename="ros2_control.xacro" />
  </xacro:if>

  <!-- <xacro:unless value="$(arg use_ros2_control)">
    <xacro:include filename="gazebo_control.xacro" />
  </xacro:unless> -->

  <!-- Make the body-->
  <xacro:sigyn_base body_props="${props.body}" wheels_props="${props.wheels}" />

  <!-- Make the wheels-->
  <xacro:wheels config="${props}" instances="${props.wheels.instances}" />

  <!-- Make the caster wheel -->
  <xacro:caster_wheel config="${props}" />

  <xacro:include filename="$(find description)/urdf/ld06.urdf.xacro" />
  <xacro:include filename="$(find description)/urdf/gazebo.urdf.xacro" />
  <xacro:ld06 lidar_prefix="top_lidar">
    <origin xyz="0.155 0 0.300" rpy="0 0 -${pi / 2}" />
  </xacro:ld06>

  <material name="red">
    <color rgba="0.8 0.0 0.0 1.0"/>
  </material>

  <joint name="servo1_joint" type="continuous">
    <parent link="base_link" />
    <child link="servo1" />
    <origin xyz="0.0 0.0 1.0" rpy="0 0 0" />
    <axis xyz="0 1 0"/>
    <dynamics damping="0.7"/>
    <limit lower="-10" upper="10" effort="100" velocity="1.0"/>

    <material name="red">
      <color rgba="0.8 0.0 0.0 1.0"/>
    </material>
  </joint>

  <link name="servo1">
    <inertial>
      <origin xyz="0 0 0" />
      <mass value="0.1" />
      <inertia ixx="0.0001" ixy="0.0" ixz="0.0" iyy="0.0001" iyz="0.0" izz="0.0001" />
    </inertial>
    <visual>
      <origin xyz="0 0 1" />
      <geometry>
        <cylinder radius="0.05" length="0.2" />
      </geometry>
      <material name="red" />
    </visual>
    <collision>
      <origin xyz="0 0 1" />
      <geometry>
        <cylinder radius="0.05" length="0.2" />
      </geometry>
    </collision>
  </link>

  <gazebo>
    <plugin filename="gz-sim-joint-position-controller-system" name="gz::sim::systems::JointPositionController">
      <joint_name>servo1_joint</joint_name>
      <!-- <sub_topic>servo1</sub_topic> -->
      <p_gain>1.0</p_gain>
      <i_gain>0.0</i_gain>
      <d_gain>0.0</d_gain>
      <i_max>0.0</i_max>
      <i_min>0.0</i_min>

      <cmd_max>1</cmd_max>
      <cmd_min>-1</cmd_min>
      <!-- <type>COMMAND</type> -->
      <topic>/servo1/position</topic>
    </plugin>
  </gazebo>

  <xacro:diff_drive_controller config="${props}" instances1="${props.wheels.instances}" instances2="${props.wheels.instances}" />
</robot>